Workbook

Sheet In Produk
B5: NO | C5: NAMA BARANG | D5: SATUAN | E5: HARGA PENAWARAN | F5: HARGA PENAWARAN | G5: HARGA NEGOSIASI | H5: QTY | I5: JML HARGA NEGOSIASI | J5: JUMLAH HARGA PENAWARAN
B6: 1 | C6: Kertas Karton | D6: Buah | E6: =ROUNDDOWN(F6,-3) -> 4000 | F6: =G6/0.99 -> 4040.404 | G6: 4000 | H6: 44 | I6: =G6*H6 -> 176000 | J6: =H6*E6 -> 176000
B7: 2 | C7: kertas HVS A4 | D7: Rim | E7: =ROUNDDOWN(F7,-3) -> 55000 | F7: =G7/0.99 -> 55555.556 | G7: 55000 | H7: 25 | I7: =G7*H7 -> 1375000 | J7: =H7*E7 -> 1375000
B8: 3 | C8: kertas HVS F4 | D8: Rim | E8: =ROUNDDOWN(F8,-3) -> 60000 | F8: =G8/0.99 -> 60606.061 | G8: 60000 | H8: 25 | I8: =G8*H8 -> 1500000 | J8: =H8*E8 -> 1500000
B9: 4 | C9: Kertas Manila | D9: Pak | E9: =ROUNDDOWN(F9,-3) -> 3000 | F9: =G9/0.99 -> 3030.303 | G9: 3000 | H9: 23 | I9: =G9*H9 -> 69000 | J9: =H9*E9 -> 69000
B10: 5 | C10: Kertas lipat | D10: pak | E10: =ROUNDDOWN(F10,-3) -> 15000 | F10: =G10/0.99 -> 15151.515 | G10: 15000 | H10: 12 | I10: =G10*H10 -> 180000 | J10: =H10*E10 -> 180000
B11: 6 | C11: Kertas cover ukuran kwarto/A4 | D11: Pak | E11: =ROUNDDOWN(F11,-3) -> 56000 | F11: =G11/0.99 -> 56565.657 | G11: 56000 | H11: 30 | I11: =G11*H11 -> 1680000 | J11: =H11*E11 -> 1680000
B12: 7 | C12: Kertas cover ukuran folio warna | D12: Pak | E12: =ROUNDDOWN(F12,-3) -> 60000 | F12: =G12/0.99 -> 60606.061 | G12: 60000 | H12: 30 | I12: =G12*H12 -> 1800000 | J12: =H12*E12 -> 1800000
B13: 8 | C13: Cover dari Plastik | D13: Pak | E13: =ROUNDDOWN(F13,-3) -> 48000 | F13: =G13/0.99 -> 48484.848 | G13: 48000 | H13: 10 | I13: =G13*H13 -> 480000 | J13: =H13*E13 -> 480000
B14: 9 | C14: Amplop Besar | D14: Dus | E14: =ROUNDDOWN(F14,-3) -> 31000 | F14: =G14/0.99 -> 31313.131 | G14: 31000 | H14: 10 | I14: =G14*H14 -> 310000 | J14: =H14*E14 -> 310000
B15: 10 | C15: Amplop Kecil | D15: Dus | E15: =ROUNDDOWN(F15,-3) -> 25000 | F15: =G15/0.99 -> 25252.525 | G15: 25000 | H15: 10 | I15: =G15*H15 -> 250000 | J15: =H15*E15 -> 250000
B16: 11 | C16: Amplop Coklat | D16: Pak | E16: =ROUNDDOWN(F16,-3) -> 28000 | F16: =G16/0.99 -> 28282.828 | G16: 28000 | H16: 10 | I16: =G16*H16 -> 280000 | J16: =H16*E16 -> 280000
B17: 12 | C17: Kertas buffalo | D17: Buah | E17: =ROUNDDOWN(F17,-3) -> 40000 | F17: =G17/0.99 -> 40404.04 | G17: 40000 | H17: 10 | I17: =G17*H17 -> 400000 | J17: =H17*E17 -> 400000
... B22: 17 | C22: Lakban Bening 5 cm | D22: Buah | E22: =ROUNDDOWN(F22,-3) -> 15000 | F22: =G22/0.99 -> 15151.515 | G22: 15000 | H22: 10 | I22: =G22*H22 -> 150000 | J22: =H22*E22 -> 150000
B23: 18 | E23: =ROUNDDOWN(F23,-3) -> 0 | F23: =G23/0.99 -> 0 | I23: =G23*H23 -> 0 | J23: =H23*E23 -> 0
B24: 19 | E24: =ROUNDDOWN(F24,-3) -> 0 | F24: =G24/0.99 -> 0 | I24: =G24*H24 -> 0 | J24: =H24*E24 -> 0
B25: 20 | E25: =ROUNDDOWN(F25,-3) -> 0 | F25: =G25/0.99 -> 0 | I25: =G25*H25 -> 0 | J25: =H25*E25 -> 0
B26: 21 | E26: =ROUNDDOWN(F26,-3) -> 0 | F26: =G26/0.99 -> 0 | I26: =G26*H26 -> 0 | J26: =H26*E26 -> 0
B27: 22 | E27: =ROUNDDOWN(F27,-3) -> 0 | F27: =G27/0.99 -> 0 | I27: =G27*H27 -> 0 | J27: =H27*E27 -> 0
B28: 23 | E28: =ROUNDDOWN(F28,-3) -> 0 | F28: =G28/0.99 -> 0 | I28: =G28*H28 -> 0 | J28: =H28*E28 -> 0
B29: 24 | E29: =ROUNDDOWN(F29,-3) -> 0 | F29: =G29/0.99 -> 0 | I29: =G29*H29 -> 0 | J29: =H29*E29 -> 0
B30: 25 | E30: =ROUNDDOWN(F30,-3) -> 0 | F30: =G30/0.99 -> 0 | I30: =G30*H30 -> 0 | J30: =H30*E30 -> 0
B31: 26 | E31: =ROUNDDOWN(F31,-3) -> 0 | F31: =G31/0.99 -> 0 | I31: =G31*H31 -> 0 | J31: =H31*E31 -> 0
B32: 27 | E32: =ROUNDDOWN(F32,-3) -> 0 | F32: =G32/0.99 -> 0 | I32: =G32*H32 -> 0 | J32: =H32*E32 -> 0
B33: 28 | E33: =ROUNDDOWN(F33,-3) -> 0 | F33: =G33/0.99 -> 0 | I33: =G33*H33 -> 0 | J33: =H33*E33 -> 0
B34: 29 | E34: =ROUNDDOWN(F34,-3) -> 0 | F34: =G34/0.99 -> 0 | I34: =G34*H34 -> 0 | J34: =H34*E34 -> 0
B35: JUMLAH | E35: =SUM(E6:E8) -> 119000 | F35: =SUM(F6:F8) -> 120202.02 | G35: =SUM(G6:G8) -> 119000 | H35: =SUM(H6:H12) -> 189 | I35: =SUM(I6:I34) -> 15000000 | J35: =SUM(J6:J34) -> 15042000
E36: PPN | G36: 1 | H36: =(I35*100/111)*11% -> 1486486.5 | I36: =G36*H36 -> 1486486.5
E37: PPh 22 | G37: 0 | H37: =(I35-H36)*1.5% -> 202702.7 | I37: =G37*H37 -> 0
E38: PPh 23 | G38: 0 | H38: =I35*2% -> 300000 | I38: =G38*H38 -> 0
E39: JUMLAH SETEALH PAJAK | I39: =I35-I36-I37-I38 -> 13513514
E45: ISI ANGKA 1 APABILA DIKENAKAN PAJAK PPN atau PPh
E46: ISI ANGKA 0 APABILA TIDAK DIKENAKAN PPN atau PPh
E48: ISI SESUAI ANGKA YANG TERTERA DI RKSAS

Sheet In Data
A2: A. | B2: PROSES DAN BERITA ACARA
A3: NO | B3: URAIAN KEGIATAN | C3: NOMOR SURAT | D3: TANGGAL PELAKSANAAN | E3: ANGKA | F3: HARI | G3: TANGGAL | H3: TANGGAL | I3: BULAN | J3: TAHUN | K3: TAHUN | L3: WAKTU
E4: TANGGAL | F4: HURUF | G4: ANGKA | H4: HURUF | I4: HURUF | J4: ANGKA | K4: HURUF
A5: 1 | B5: DOKUMEN PERENCANAAN | C5: 900/......../SMAN.01/CADISDIKWIL.VI/......./2026 | D5: =D6 -> 46053 | E5: 20 Agustus 2026 | F5: =TEXT(D5, "[$-id]dddd") -> Sabtu | G5: =DAY(D5) -> 31 | H5: =PROPER([1]!terbilang(G5)) -> #NAME? | I5: =TEXT(D5,"[$-id]mmmm") -> Januari | J5: =TEXT(D5,"yyyy") -> 2026 | K5: =PROPER([1]!terbilang(J5)) -> #NAME?
A6: 2 | B6: DOKUMEN HASIL NEGOSIASI | C6: 900/......../SMAN.01/CADISDIKWIL.VI/......./2026 | D6: =D7-2 -> 46053 | E6: 20 Agustus 2026 | F6: =TEXT(D6, "[$-id]dddd") -> Sabtu | G6: =DAY(D6) -> 31 | H6: =PROPER([1]!terbilang(G6)) -> #NAME? | I6: =TEXT(D6,"[$-id]mmmm") -> Januari | J6: =TEXT(D6,"yyyy") -> 2026 | K6: =PROPER([1]!terbilang(J6)) -> #NAME?
A7: 3 | B7: SURAT PEMESANAN | C7: 900/......../SMAN.01/CADISDIKWIL.VI/......./2026 | D7: =D8-1 -> 46055 | E7: 02 Februari 2026 | F7: =TEXT(D7, "[$-id]dddd") -> Senin | G7: =DAY(D7) -> 2 | H7: =PROPER([1]!terbilang(G7)) -> #NAME? | I7: =TEXT(D7,"[$-id]mmmm") -> Februari | J7: =TEXT(D7,"yyyy") -> 2026 | K7: =PROPER([1]!terbilang(J7)) -> #NAME?
A8: 4 | B8: SURAT HASIL PEMERIKSAAN BARANG | C8: 900/......../SMAN.01/CADISDIKWIL.VI/......./2026 | D8: =D9 -> 46056 | E8: 03 Februari 2026 | F8: =TEXT(D8, "[$-id]dddd") -> Selasa | G8: =DAY(D8) -> 3 | H8: =PROPER([1]!terbilang(G8)) -> #NAME? | I8: =TEXT(D8,"[$-id]mmmm") -> Februari | J8: =TEXT(D8,"yyyy") -> 2026 | K8: =PROPER([1]!terbilang(J8)) -> #NAME?
A9: 5 | B9: BERITA ACARA SERAH TERIMA | C9: 900/......../SMAN.01/CADISDIKWIL.VI/......./2026 | D9: =D10-0 -> 46056 | E9: 03 Februari 2026 | F9: =TEXT(D9, "[$-id]dddd") -> Selasa | G9: =DAY(D9) -> 3 | H9: =PROPER([1]!terbilang(G9)) -> #NAME? | I9: =TEXT(D9,"[$-id]mmmm") -> Februari | J9: =TEXT(D9,"yyyy") -> 2026 | K9: =PROPER([1]!terbilang(J9)) -> #NAME?
A10: 6 | B10: FAKTUR | C10: 030101/CV.AFWAN/02/2026 | D10: =D11-2 -> 46056 | E10: 03 Februari 2026 | F10: =TEXT(D10, "[$-id]dddd") -> Selasa | G10: =DAY(D10) -> 3 | H10: =PROPER([1]!terbilang(G10)) -> #NAME? | I10: =TEXT(D10,"[$-id]mmmm") -> Februari | J10: =TEXT(D10,"yyyy") -> 2026 | K10: =PROPER([1]!terbilang(J10)) -> #NAME?
A11: 7 | B11: KUITANSI | C11: 050102/CV.AFWAN/02/2026 | D11: 46058 | E11: 05 Februari 2026 | F11: =TEXT(D11, "[$-id]dddd") -> Kamis | G11: =DAY(D11) -> 5 | H11: =PROPER([1]!terbilang(G11)) -> #NAME? | I11: =TEXT(D11,"[$-id]mmmm") -> Februari | J11: =TEXT(D11,"yyyy") -> 2026 | K11: =PROPER([1]!terbilang(J11)) -> #NAME?
A13: B. | B13: BAHAN KOP SURAT
A14: No. | B14: Uraian | C14: Keterangan
A15: 1 | B15: K/L/D/I PUSAT | C15: PEMERINTAH DAERAH PROVINSI JAWA BARAT
A16: 2 | B16: K/L/D/I PROPINSI | C16: DINAS PENDIDIKAN
A17: 3 | B17: NAMA SATUAN PENDIDIKAN | C17: CABANG DINAS PENDIDIKAN WILAYAH VI
A18: 4 | B18: ALAMAT SATUAN PENDIDIKAN | C18: SMA NEGERI 1 PAGELARAN
A19: 5 | B19: ALAMAT | C19: Jalan Raya Pagelaran Kp. Cibeureum Desa Sindangkerta Rt. 06/Rw. 07 Pagelaran – Cianjur 43266
C20: Tlp.(0263) 236150 e-mail : smanpagelaran@gmail.com | D20: (0263) 363023/363021, 43267
B21: TELEPON | C21: Jalan Raya Pagelaran Kp. Cibeureum Desa Sindangkerta Rt. 06/Rw. 07 Pagelaran – Cianjur 43266
B22: TELEPON | C22: 0263-236150
A23: C. | B23: PELAKSANA | C23: Jalan Raya Pagelaran Kp. Cibeureum Desa Sindangkerta Rt. 06/Rw. 07 Pagelaran – Cianjur 43266
A24: No. | B24: Uraian | C24: Keterangan
A25: 1 | B25: NAMA JABATAN | C25: Kepala Sekolah
A26: 2 | B26: NAMA JABATAN | C26: Fitri Yurnita, S.Pd
A27: 3 | B27: NIP | C27: 198008142009032002
A29: D. | B29: PEMERIKSA BARANG
A30: No. | B30: Uraian | C30: Keterangan
A31: 1 | B31: NAMA JABATAN | C31: Pemeriksa Barang
A32: 3 | B32: NAMA | C32: Hamdani
A33: 4 | B33: NIP | C33: -
A35: E. | B35: DATA PAKET PEKERJAAN
A36: No. | B36: Data Paket | C36: Keterangan
A37: 1 | B37: YANG MENYERAHKAN PEMBAYARAN | C37: ="Bendaraha "&C50&"" -> Bendaraha BOSP
A38: 2 | B38: KATEGORI BARANG/JASA | C38: Belanja Alat Tulis Kantor
A39: 3 | B39: NILAI HARGA PENAWARAN | C39: ='In Produk'!J35 -> 15042000
A40: 4 | B40: TERBILANG NILAI HARGA PENAWARAN | C40: =PROPER([1]!terbilang(C39)&" Rupiah"&"") -> #NAME?
A41: 5 | B41: NILAI HARGA NEGOSIASI | C41: ='In Produk'!I35 -> 15000000
A42: 6 | B42: TERBILANG NILAI KONTRAK | C42: =PROPER([1]!terbilang(C41)&" Rupiah") -> #NAME?
B43: NILAI HARGA NEGOSIASI KETIK | C43: Rp. 15.000.000
B44: TERBILANG KETIK | C44: =C42 -> #NAME?
...

Sheet Dok Perencanaan
C3: ='In Data'!C15 -> PEMERINTAH DAERAH PROVINSI JAWA BARAT
C4: ='In Data'!C16 -> DINAS PENDIDIKAN
C5: ='In Data'!C17 -> CABANG DINAS PENDIDIKAN WILAYAH VI
C6: ='In Data'!C18 -> SMA NEGERI 1 PAGELARAN
C7: ='In Data'!C20 -> Tlp.(0263) 236150 e-mail : smanpagelaran@gmail.com
C8: ='In Data'!C21 -> Jalan Raya Pagelaran Kp. Cibeureum Desa Sindangkerta Rt. 06/Rw. 07 Pagelaran – Cianjur 43266
C10: DOKUMEN PERENCANAAN
C11: ='In Data'!C5 -> 900/......../SMAN.01/CADISDIKWIL.VI/......./2026
C13: NAMA SATUAN PENDIDIKAN | E13: : | F13: ='In Data'!C18 -> SMA NEGERI 1 PAGELARAN
C14: ALAMAT SATUAN PENDIDIKAN | E14: : | F14: ='In Data'!C23 -> Jalan Raya Pagelaran Kp. Cibeureum Desa Sindangkerta Rt. 06/Rw. 07 Pagelaran – Cianjur 43266
C15: KATEGORI BARANG/JASA | E15: : | F15: ='In Data'!C38 -> Belanja Alat Tulis Kantor
C17: NO | D17: JENIS | G17: KETERANGAN
C18: 1 | D18: JUMLAH BARANG/JASA | G18: ='In Produk'!H35 -> 189
C19: 2 | D19: TOTAL ANGGARAN | G19: ='In Data'!C41 -> 15000000
C20: 3 | D20: TANGGAL MULAI PEKERJAAN | G20: ='In Data'!C45 -> 02 Februari 2026
C21: 4 | D21: TANGGAL SELESAI PEKERJAAN | G21: ='In Data'!C46 -> 03 Februari 2026
C22: 5 | D22: LAMA PENGERJAAN | G22: ='In Data'!C48 -> 2 HARI
C23: 6 | D23: SUMBER ANGGARAN | G23: ='In Data'!C50 -> BOSP
C24: 7 | D24: TAHUN ANGGARAN | G24: ='In Data'!C49 -> 2026
C25: 8 | D25: PERSYARATAN PENYEDIA | G25: PERORANGAN/BADAN USAHA
G26: MEMENUHI SYARAT SEBAGAI BERIKUT :
G27: A. IDENTITAS PENYEDIA
G28: B. NOMOR POKOK WAJIB PAJAK (NPWP)
G29: C. NOMOR INDUK BERUSAHA (NIB)
G30: D. BUKTI LAPORAN PAJAK TAHUN TERAKHIR
G32: ="Cianjur "&'In Data'!E5&"" -> Cianjur 20 Agustus 2026
G33: Pelaksana
G41: ='In Data'!C26 -> Fitri Yurnita, S.Pd
G42: ="NIP. "&'In Data'!C27&"" -> NIP. 198008142009032002

Sheet Dok Hasil Nego
C2: ='In Data'!C15 -> PEMERINTAH DAERAH PROVINSI JAWA BARAT
C3: ='In Data'!C16 -> DINAS PENDIDIKAN
C4: ='In Data'!C17 -> CABANG DINAS PENDIDIKAN WILAYAH VI
C5: ='In Data'!C18 -> SMA NEGERI 1 PAGELARAN
C6: ='In Data'!C20 -> Tlp.(0263) 236150 e-mail : smanpagelaran@gmail.com
C7: ='In Data'!C21 -> Jalan Raya Pagelaran Kp. Cibeureum Desa Sindangkerta Rt. 06/Rw. 07 Pagelaran – Cianjur 43266
C9: DOKUMEN HASIL NEGOSIASI
C10: ='In Data'!C6 -> 900/......../SMAN.01/CADISDIKWIL.VI/......./2026
C13: NAMA SATUAN PENDIDIKAN | E13: : | F13: ='In Data'!C18 -> SMA NEGERI 1 PAGELARAN
C14: ALAMAT SATUAN PEDIDIKAN | E14: : | F14: ='In Data'!C19 -> Jalan Raya Pagelaran Kp. Cibeureum Desa Sindangkerta Rt. 06/Rw. 07 Pagelaran – Cianjur 43266
C15: NAMA CALON PENYEDIA | E15: : | F15: ='In Data'!C68 -> CV. AFWAN
C16: ALAMAT CALON PENYEDIA | E16: : | F16: ='In Data'!C69 -> Kp. Cangklek No. 61 RT.004 / RW.001 Sukamanah, Cugenang, Cianjur Jawa barat
C17: TANGGAL TERIMA BARANG/JASA | E17: : | F17: ='In Data'!E8 -> 03 Februari 2026
C18: HASIL NEGOSIASI | E18: : | F18: ='In Data'!C41 -> 15000000
C20: NO | D20: NAMA PRODUK | F20: JUMLAH (QTY) | G20: HARGA PENAWARAN | H20: HARGA NEGOSIASI | I20: JUMLAH HARGA PENAWARAN | J20: JUMLAH HARGA NEGOSIASI | K20: KETERANGAN
C21: ='In Produk'!B6 -> 1 | D21: ='In Produk'!C6 -> Kertas Karton | F21: ='In Produk'!H6 -> 44 | G21: ='In Produk'!E6 -> 4000 | H21: ='In Produk'!I6 -> 176000 | I21: ='In Produk'!J6 -> 176000 | J21: ='In Produk'!I6 -> 176000
C22: ='In Produk'!B7 -> 2 | D22: ='In Produk'!C7 -> kertas HVS A4 | F22: ='In Produk'!H7 -> 25 | G22: ='In Produk'!E7 -> 55000 | H22: ='In Produk'!I7 -> 1375000 | I22: ='In Produk'!J7 -> 1375000 | J22: ='In Produk'!I7 -> 1375000
C23: ='In Produk'!B8 -> 3 | D23: ='In Produk'!C8 -> kertas HVS F4 | F23: ='In Produk'!H8 -> 25 | G23: ='In Produk'!E8 -> 60000 | H23: ='In Produk'!I8 -> 1500000 | I23: ='In Produk'!J8 -> 1500000 | J23: ='In Produk'!I8 -> 1500000
C24: ='In Produk'!B9 -> 4 | D24: ='In Produk'!C9 -> Kertas Manila | F24: ='In Produk'!H9 -> 23 | G24: ='In Produk'!E9 -> 3000 | H24: ='In Produk'!I9 -> 69000 | I24: ='In Produk'!J9 -> 69000 | J24: ='In Produk'!I9 -> 69000
C25: ='In Produk'!B10 -> 5 | D25: ='In Produk'!C10 -> Kertas lipat | F25: ='In Produk'!H10 -> 12 | G25: ='In Produk'!E10 -> 15000 | H25: ='In Produk'!I10 -> 180000 | I25: ='In Produk'!J10 -> 180000 | J25: ='In Produk'!I10 -> 180000
C26: ='In Produk'!B11 -> 6 | D26: ='In Produk'!C11 -> Kertas cover ukuran kwarto/A4 | F26: ='In Produk'!H11 -> 30 | G26: ='In Produk'!E11 -> 56000 | H26: ='In Produk'!I11 -> 1680000 | I26: ='In Produk'!J11 -> 1680000 | J26: ='In Produk'!I11 -> 1680000
C27: ='In Produk'!B12 -> 7 | D27: ='In Produk'!C12 -> Kertas cover ukuran folio warna | F27: ='In Produk'!H12 -> 30 | G27: ='In Produk'!E12 -> 60000 | H27: ='In Produk'!I12 -> 1800000 | I27: ='In Produk'!J12 -> 1800000 | J27: ='In Produk'!I12 -> 1800000
C28: JUMLAH TOTAL | F28: =SUM(F21:F27) -> 189 | I28: =SUM(I21:I27) -> 6780000 | J28: =SUM(J21:J27) -> 6780000
K30: ="Cianjur, "&'In Data'!E6&"" -> Cianjur, 20 Agustus 2026
D31: Calon Penyedia | K31: Pelaksana
D36: ='In Data'!C54 -> Mega Afriyanti, S.Pd | K36: ='In Data'!C26 -> Fitri Yurnita, S.Pd
D37: ='[2]INPUT DATA'!C56 -> Direktur | K37: ="NIP. "&'In Data'!C27&"" -> NIP. 198008142009032002

Sheet Surat Pesanan
C3: ='In Data'!C15 -> PEMERINTAH DAERAH PROVINSI JAWA BARAT
C4: ='In Data'!C16 -> DINAS PENDIDIKAN
C5: ='In Data'!C17 -> CABANG DINAS PENDIDIKAN WILAYAH VI
C6: ='In Data'!C18 -> SMA NEGERI 1 PAGELARAN
C7: ='In Data'!C20 -> Tlp.(0263) 236150 e-mail : smanpagelaran@gmail.com
C8: ='In Data'!C21 -> Jalan Raya Pagelaran Kp. Cibeureum Desa Sindangkerta Rt. 06/Rw. 07 Pagelaran – Cianjur 43266
C10: SURAT PESANAN (SP)
C11: ='In Data'!C7 -> 900/......../SMAN.01/CADISDIKWIL.VI/......./2026
C12: ="Tanggal "&'In Data'!E7&"" -> Tanggal 02 Februari 2026
C14: Sub Pekerjaan :
C15: ='In Data'!C38 -> Belanja Alat Tulis Kantor
C16: ="Pada "&'In Data'!C18&"" -> Pada SMA NEGERI 1 PAGELARAN
C18: Yang bertanda tangan di bawah ini :
C19: 1. | D19: Nama | E19: : | F19: ='In Data'!C26 -> Fitri Yurnita, S.Pd
D20: Jabatan | E20: : | F20: Kepala Sekolah
D21: Alamat | E21: : | F21: ='In Data'!C21 -> Jalan Raya Pagelaran Kp. Cibeureum Desa Sindangkerta Rt. 06/Rw. 07 Pagelaran – Cianjur 43266
C22: Yang selanjutnya disebut PIHAK KE 1
C24: 2. | D24: Nama | E24: : | F24: ='In Data'!C54 -> Mega Afriyanti, S.Pd
D25: Jabatan | E25: : | F25: ='In Data'!C58 -> Direktur
D26: NPWP | E26: : | F26: ='In Data'!C59 -> -
D27: Alamat Perusahaan | E27: : | F27: ='In Data'!C69 -> Kp. Cangklek No. 61 RT.004 / RW.001 Sukamanah, Cugenang, Cianjur Jawa barat
C28: Yang selanjutnya disebut PIHAK KE 2
C30: ="Berdasarkan dokumen perencanaan nomor "&'In Data'!C5&" pada kegiatan "&'In Data'!C38&", dengan ini kami sampaikan rincian pesanan sebagai berikut :" -> Berdasarkan dokumen perencanaan nomor 900/......../SMAN.01/CADISDIKWIL.VI/......./2026 pada kegiatan Belanja Alat Tulis Kantor, dengan ini kami sampaikan rincian pesanan sebagai berikut :
C31: NO | D31: NAMA PRODUK | G31: HARGA SATUAN | H31: QTY | I31: JML HARGA
C32: ='In Produk'!B6 -> 1 | D32: ='In Produk'!C6 -> Kertas Karton | G32: ='In Produk'!G6 -> 4000 | H32: ='In Produk'!H6 -> 44 | I32: ='In Produk'!I6 -> 176000
C33: ='In Produk'!B7 -> 2 | D33: ='In Produk'!C7 -> kertas HVS A4 | G33: ='In Produk'!G7 -> 55000 | H33: ='In Produk'!H7 -> 25 | I33: ='In Produk'!I7 -> 1375000
C34: ='In Produk'!B8 -> 3 | D34: ='In Produk'!C8 -> kertas HVS F4 | G34: ='In Produk'!G8 -> 60000 | H34: ='In Produk'!H8 -> 25 | I34: ='In Produk'!I8 -> 1500000
C35: ='In Produk'!B9 -> 4 | D35: ='In Produk'!C9 -> Kertas Manila | G35: ='In Produk'!G9 -> 3000 | H35: ='In Produk'!H9 -> 23 | I35: ='In Produk'!I9 -> 69000
C36: ='In Produk'!B10 -> 5 | D36: ='In Produk'!C10 -> Kertas lipat | G36: ='In Produk'!G10 -> 15000 | H36: ='In Produk'!H10 -> 12 | I36: ='In Produk'!I10 -> 180000
C37: ='In Produk'!B11 -> 6 | D37: ='In Produk'!C11 -> Kertas cover ukuran kwarto/A4 | G37: ='In Produk'!G11 -> 56000 | H37: ='In Produk'!H11 -> 30 | I37: ='In Produk'!I11 -> 1680000
C38: ='In Produk'!B12 -> 7 | D38: ='In Produk'!C12 -> Kertas cover ukuran folio warna | G38: ='In Produk'!G12 -> 60000 | H38: ='In Produk'!H12 -> 30 | I38: ='In Produk'!I12 -> 1800000
C39: ='In Produk'!B13 -> 8 | D39: ='In Produk'!C13 -> Cover dari Plastik | G39: ='In Produk'!G13 -> 48000 | H39: ='In Produk'!H13 -> 10 | I39: ='In Produk'!I13 -> 480000
C40: ='In Produk'!B14 -> 9 | D40: ='In Produk'!C14 -> Amplop Besar | G40: ='In Produk'!G14 -> 31000 | H40: ='In Produk'!H14 -> 10 | I40: ='In Produk'!I14 -> 310000
C41: ='In Produk'!B15 -> 10 | D41: ='In Produk'!C15 -> Amplop Kecil | G41: ='In Produk'!G15 -> 25000 | H41: ='In Produk'!H15 -> 10 | I41: ='In Produk'!I15 -> 250000
C42: ='In Produk'!B16 -> 11 | D42: ='In Produk'!C16 -> Amplop Coklat | G42: ='In Produk'!G16 -> 28000 | H42: ='In Produk'!H16 -> 10 | I42: ='In Produk'!I16 -> 280000
C43: ='In Produk'!B17 -> 12 | D43: ='In Produk'!C17 -> Kertas buffalo | G43: ='In Produk'!G17 -> 40000 | H43: ='In Produk'!H17 -> 10 | I43: ='In Produk'!I17 -> 400000
... C48: ='In Produk'!B22 -> 17 | D48: ='In Produk'!C22 -> Lakban Bening 5 cm | G48: ='In Produk'!G22 -> 15000 | H48: ='In Produk'!H22 -> 10 | I48: ='In Produk'!I22 -> 150000
H49: JUMLAH TOTAL | I49: =SUM(I32:I48) -> 15000000 | J49: =I49/1.11*11% -> 1486486.5
H50: PPN 11% | I50: ='In Produk'!I36 -> 1486486.5
H51: PPh 22 | I51: ='In Produk'!I37 -> 0
...

Sheet Surat Hasil Pemeriksaan
C2: ='In Data'!C15 -> PEMERINTAH DAERAH PROVINSI JAWA BARAT
C3: ='In Data'!C16 -> DINAS PENDIDIKAN
C4: ='In Data'!C17 -> CABANG DINAS PENDIDIKAN WILAYAH VI
C5: ='In Data'!C18 -> SMA NEGERI 1 PAGELARAN
C6: ='In Data'!C20 -> Tlp.(0263) 236150 e-mail : smanpagelaran@gmail.com
C7: ='In Data'!C21 -> Jalan Raya Pagelaran Kp. Cibeureum Desa Sindangkerta Rt. 06/Rw. 07 Pagelaran – Cianjur 43266
C9: SURAT HASIL PEMERIKSAAN
C10: ='In Data'!C8 -> 900/......../SMAN.01/CADISDIKWIL.VI/......./2026
C12: ="Pada hari ini, "&'In Data'!F8&" tanggal "&'In Data'!H8&" bulan "&'In Data'!I8&" tahun "&'In Data'!K8&" sesuai dengan :" -> #NAME?
C13: Nomor Surat Pemersanan | E13: : | F13: ='In Data'!C7 -> 900/......../SMAN.01/CADISDIKWIL.VI/......./2026
C14: Tanggal | E14: : | F14: ='In Data'!E7 -> 02 Februari 2026
C15: Nama Pekerjaan | E15: : | F15: ='In Data'!C38 -> Belanja Alat Tulis Kantor
C16: Tahun | E16: : | F16: ='In Data'!C49 -> 2026
C18: Yang bertandatangan di bawan ini
C19: Nama | E19: : | F19: ='In Data'!C26 -> Fitri Yurnita, S.Pd
C20: Jabatan | E20: : | F20: Kepala Sekolah
C21: Nama Satuan Pendidikan | E21: : | F21: ='In Data'!C18 -> SMA NEGERI 1 PAGELARAN
C22: Alamat Satuan Pendidikan | E22: : | F22: ='In Data'!C21 -> Jalan Raya Pagelaran Kp. Cibeureum Desa Sindangkerta Rt. 06/Rw. 07 Pagelaran – Cianjur 43266
C24: Telah melakukan pemeriksaan terhadap hasil pekerjaan sesuai surat pemesanan dimaksud dengan rincian berikut :
C26: No | D26: Nama Barang/Jasa | F26: Jumlah | G26: Jumlah Yang Diterima | H26: Kondisi
H27: Kurang | I27: Baik | J27: Rusak
C28: ='In Produk'!B6 -> 1 | D28: ='In Produk'!C6 -> Kertas Karton | F28: ='In Produk'!H6 -> 44
C29: ='In Produk'!B7 -> 2 | D29: ='In Produk'!C7 -> kertas HVS A4 | F29: ='In Produk'!H7 -> 25
C30: ='In Produk'!B8 -> 3 | D30: ='In Produk'!C8 -> kertas HVS F4 | F30: ='In Produk'!H8 -> 25
C31: ='In Produk'!B9 -> 4 | D31: ='In Produk'!C9 -> Kertas Manila | F31: ='In Produk'!H9 -> 23
C32: ='In Produk'!B10 -> 5 | D32: ='In Produk'!C10 -> Kertas lipat | F32: ='In Produk'!H10 -> 12
C33: ='In Produk'!B11 -> 6 | D33: ='In Produk'!C11 -> Kertas cover ukuran kwarto/A4 | F33: ='In Produk'!H11 -> 30
C34: ='In Produk'!B12 -> 7 | D34: ='In Produk'!C12 -> Kertas cover ukuran folio warna | F34: ='In Produk'!H12 -> 30
C35: ='In Produk'!B13 -> 8 | D35: ='In Produk'!C13 -> Cover dari Plastik | F35: ='In Produk'!H13 -> 10
C36: ='In Produk'!B14 -> 9 | D36: ='In Produk'!C14 -> Amplop Besar | F36: ='In Produk'!H14 -> 10
C37: ='In Produk'!B15 -> 10 | D37: ='In Produk'!C15 -> Amplop Kecil | F37: ='In Produk'!H15 -> 10
C38: ='In Produk'!B16 -> 11 | D38: ='In Produk'!C16 -> Amplop Coklat | F38: ='In Produk'!H16 -> 10
C39: ='In Produk'!B17 -> 12 | D39: ='In Produk'!C17 -> Kertas buffalo | F39: ='In Produk'!H17 -> 10
... C44: ='In Produk'!B22 -> 17 | D44: ='In Produk'!C22 -> Lakban Bening 5 cm | F44: ='In Produk'!H22 -> 10
C46: Demikian Surat Pemeriksaan Hasil Pekerjaan ini dibuat dengan sebenarnya untuk dipergunakan sebagaimana seharusnya.
D48: PIHAK KEDUA | H48: PIHAK PERTAMA
D49: Kepala Sekolah | H49: ='In Data'!C68 -> CV. AFWAN
D56: ='In Data'!C26 -> Fitri Yurnita, S.Pd | H56: ='In Data'!C54 -> Mega Afriyanti, S.Pd
D57: ="NIP. "&'In Data'!C27&"" -> NIP. 198008142009032002 | H57: ='[2]INPUT DATA'!C56 -> Direktur
F59: PEMERIKSA BARANG
...

Sheet Berita Acara Serah Terima
C3: ='In Data'!C15 -> PEMERINTAH DAERAH PROVINSI JAWA BARAT
C4: ='In Data'!C16 -> DINAS PENDIDIKAN
C5: ='In Data'!C17 -> CABANG DINAS PENDIDIKAN WILAYAH VI
D6: ='In Data'!C18 -> SMA NEGERI 1 PAGELARAN
C7: ='In Data'!C20 -> Tlp.(0263) 236150 e-mail : smanpagelaran@gmail.com
C8: ='In Data'!C21 -> Jalan Raya Pagelaran Kp. Cibeureum Desa Sindangkerta Rt. 06/Rw. 07 Pagelaran – Cianjur 43266
C10: BERITA ACARA SERAH TERIMA
C11: ='In Data'!C9 -> 900/......../SMAN.01/CADISDIKWIL.VI/......./2026
C13: ="Pada hari ini "&'In Data'!F9&" tanggal "&'In Data'!H9&" bulan "&'In Data'!I9&" tahun "&'In Data'!K9&" sesuai dengan :" -> #NAME?
C14: Nomor Surat Pemersanan | E14: : | F14: ='In Data'!C7 -> 900/......../SMAN.01/CADISDIKWIL.VI/......./2026
C15: Tanggal | E15: : | F15: ='In Data'!E7 -> 02 Februari 2026
C16: Nama Pekerjaan | E16: : | F16: ='In Data'!C38 -> Belanja Alat Tulis Kantor
C17: Tahun | E17: : | F17: ='In Data'!C49 -> 2026
C19: Yang bertandatangan di bawan ini
C20: 1 | D20: Nama | E20: : | F20: ='In Data'!C54 -> Mega Afriyanti, S.Pd
D21: Jabatan | E21: : | F21: ='In Data'!C58 -> Direktur
D22: Nama Penyedia | E22: : | F22: ='In Data'!C68 -> CV. AFWAN
D23: Alamat Penyedia | E23: : | F23: ='In Data'!C69 -> Kp. Cangklek No. 61 RT.004 / RW.001 Sukamanah, Cugenang, Cianjur Jawa barat
D24: Nomor Telepon | E24: : | F24: ='In Data'!C60 -> 085691768167
D25: Sebagai pihak yang menyerahkan, selanjutnya disebut PIHAK PERTAMA
C27: 2 | D27: Nama | E27: : | F27: ='In Data'!C26 -> Fitri Yurnita, S.Pd
D28: Jabatan | E28: : | F28: Kepala Sekolah
D29: Nama Satuan Pendidikan | E29: : | F29: ='In Data'!C18 -> SMA NEGERI 1 PAGELARAN
D30: Alamat Satuan Pendidikan | E30: : | F30: ='In Data'!C21 -> Jalan Raya Pagelaran Kp. Cibeureum Desa Sindangkerta Rt. 06/Rw. 07 Pagelaran – Cianjur 43266
D31: Nomor Telepon | E31: : | F31: ='In Data'!C22 -> 0263-236150
D32: Sebagai pihak yang menerima, selanjutnya disebut PIHAK KEDUA
C34: ="PIHAK PERTAMA menyerahkan hasil pekerjaan "&'In Data'!C38&" kepada PIHAK KEDUA, dan PIHAK KEDUA telah menerima hasil pekerjaan tersebut dalam jumlah yang lengkap dan kondisi yang baik sesuai dengan rincian berikut:" -> PIHAK PERTAMA menyerahkan hasil pekerjaan Belanja Alat Tulis Kantor kepada PIHAK KEDUA, dan PIHAK KEDUA telah menerima hasil pekerjaan tersebut dalam jumlah yang lengkap dan kondisi yang baik sesuai dengan rincian berikut:
C36: NO | D36: NAMA BARANG/JASA | F36: JUMLAH DISERAHKAN | G36: JUMLAH DITERIMA | H36: KONDISI
H37: BAIK | I37: RUSAK
C38: ='In Produk'!B6 -> 1 | D38: ='In Produk'!C6 -> Kertas Karton | F38: ='In Produk'!H6 -> 44
C39: ='In Produk'!B7 -> 2 | D39: ='In Produk'!C7 -> kertas HVS A4 | F39: ='In Produk'!H7 -> 25
C40: ='In Produk'!B8 -> 3 | D40: ='In Produk'!C8 -> kertas HVS F4 | F40: ='In Produk'!H8 -> 25
C41: ='In Produk'!B9 -> 4 | D41: ='In Produk'!C9 -> Kertas Manila | F41: ='In Produk'!H9 -> 23
C42: ='In Produk'!B10 -> 5 | D42: ='In Produk'!C10 -> Kertas lipat | F42: ='In Produk'!H10 -> 12
C43: ='In Produk'!B11 -> 6 | D43: ='In Produk'!C11 -> Kertas cover ukuran kwarto/A4 | F43: ='In Produk'!H11 -> 30
C44: ='In Produk'!B12 -> 7 | D44: ='In Produk'!C12 -> Kertas cover ukuran folio warna | F44: ='In Produk'!H12 -> 30
C45: ='In Produk'!B13 -> 8 | D45: ='In Produk'!C13 -> Cover dari Plastik | F45: ='In Produk'!H13 -> 10
C46: ='In Produk'!B14 -> 9 | D46: ='In Produk'!C14 -> Amplop Besar | F46: ='In Produk'!H14 -> 10
C47: ='In Produk'!B15 -> 10 | D47: ='In Produk'!C15 -> Amplop Kecil | F47: ='In Produk'!H15 -> 10
C48: ='In Produk'!B16 -> 11 | D48: ='In Produk'!C16 -> Amplop Coklat | F48: ='In Produk'!H16 -> 10
...

Sheet Faktur
B10: FAKTUR
B12: Kepada Yth. | D12: No. Faktur | E12: : | F12: ='In Data'!C10 -> 030101/CV.AFWAN/02/2026
B13: ='In Data'!C18 -> SMA NEGERI 1 PAGELARAN | D13: Tanggal | E13: : | F13: ='In Data'!E10 -> 03 Februari 2026
B14: ='In Data'!C19 -> Jalan Raya Pagelaran Kp. Cibeureum Desa Sindangkerta Rt. 06/Rw. 07 Pagelaran – Cianjur 43266
B16: No | C16: Nama Produk | D16: Satuan | E16: Jumlah (QTY) | F16: Harga Satuan | G16: Total Harga
B17: ='In Produk'!B6 -> 1 | C17: ='In Produk'!C6 -> Kertas Karton | D17: ='In Produk'!D6 -> Buah | E17: ='In Produk'!H6 -> 44 | F17: ='In Produk'!G6 -> 4000 | G17: ='In Produk'!I6 -> 176000
B18: ='In Produk'!B7 -> 2 | C18: ='In Produk'!C7 -> kertas HVS A4 | D18: ='In Produk'!D7 -> Rim | E18: ='In Produk'!H7 -> 25 | F18: ='In Produk'!G7 -> 55000 | G18: ='In Produk'!I7 -> 1375000
B19: ='In Produk'!B8 -> 3 | C19: ='In Produk'!C8 -> kertas HVS F4 | D19: ='In Produk'!D8 -> Rim | E19: ='In Produk'!H8 -> 25 | F19: ='In Produk'!G8 -> 60000 | G19: ='In Produk'!I8 -> 1500000
B20: ='In Produk'!B9 -> 4 | C20: ='In Produk'!C9 -> Kertas Manila | D20: ='In Produk'!D9 -> Pak | E20: ='In Produk'!H9 -> 23 | F20: ='In Produk'!G9 -> 3000 | G20: ='In Produk'!I9 -> 69000
B21: ='In Produk'!B10 -> 5 | C21: ='In Produk'!C10 -> Kertas lipat | D21: ='In Produk'!D10 -> pak | E21: ='In Produk'!H10 -> 12 | F21: ='In Produk'!G10 -> 15000 | G21: ='In Produk'!I10 -> 180000
B22: ='In Produk'!B11 -> 6 | C22: ='In Produk'!C11 -> Kertas cover ukuran kwarto/A4 | D22: ='In Produk'!D11 -> Pak | E22: ='In Produk'!H11 -> 30 | F22: ='In Produk'!G11 -> 56000 | G22: ='In Produk'!I11 -> 1680000
B23: ='In Produk'!B12 -> 7 | C23: ='In Produk'!C12 -> Kertas cover ukuran folio warna | D23: ='In Produk'!D12 -> Pak | E23: ='In Produk'!H12 -> 30 | F23: ='In Produk'!G12 -> 60000 | G23: ='In Produk'!I12 -> 1800000
B24: ='In Produk'!B13 -> 8 | C24: ='In Produk'!C13 -> Cover dari Plastik | D24: ='In Produk'!D13 -> Pak | E24: ='In Produk'!H13 -> 10 | F24: ='In Produk'!G13 -> 48000 | G24: ='In Produk'!I13 -> 480000
B25: ='In Produk'!B14 -> 9 | C25: ='In Produk'!C14 -> Amplop Besar | D25: ='In Produk'!D14 -> Dus | E25: ='In Produk'!H14 -> 10 | F25: ='In Produk'!G14 -> 31000 | G25: ='In Produk'!I14 -> 310000
B26: ='In Produk'!B15 -> 10 | C26: ='In Produk'!C15 -> Amplop Kecil | D26: ='In Produk'!D15 -> Dus | E26: ='In Produk'!H15 -> 10 | F26: ='In Produk'!G15 -> 25000 | G26: ='In Produk'!I15 -> 250000
B27: ='In Produk'!B16 -> 11 | C27: ='In Produk'!C16 -> Amplop Coklat | D27: ='In Produk'!D16 -> Pak | E27: ='In Produk'!H16 -> 10 | F27: ='In Produk'!G16 -> 28000 | G27: ='In Produk'!I16 -> 280000
B28: ='In Produk'!B17 -> 12 | C28: ='In Produk'!C17 -> Kertas buffalo | D28: ='In Produk'!D17 -> Buah | E28: ='In Produk'!H17 -> 10 | F28: ='In Produk'!G17 -> 40000 | G28: ='In Produk'!I17 -> 400000
... B33: ='In Produk'!B22 -> 17 | C33: ='In Produk'!C22 -> Lakban Bening 5 cm | D33: ='In Produk'!D22 -> Buah | E33: ='In Produk'!H22 -> 10 | F33: ='In Produk'!G22 -> 15000 | G33: ='In Produk'!I22 -> 150000
B34: Jumlah Harga Jual | G34: =SUM(G17:G33) -> 15000000
B35: PPN 11% | G35: ='In Produk'!I36 -> 1486486.5
B36: PPh 22 | G36: ='In Produk'!I37 -> 0
B37: PPh 23 | G37: ='In Produk'!I38 -> 0
B38: Jumlah Harga Setelah Pajak | G38: ='In Produk'!I39 -> 13513514
B39: =PROPER([1]!terbilang(G34)&" Rupiah"&"") -> #NAME?
C41: Mengetahui, | F41: Hormat Kami,
C42: Kepala Sekolah | F42: ='In Data'!C68 -> CV. AFWAN
C48: ='In Data'!C26 -> Fitri Yurnita, S.Pd | F48: ='In Data'!C54 -> Mega Afriyanti, S.Pd
C49: ="NIP. "&'In Data'!C27&"" -> NIP. 198008142009032002 | F49: ='[2]INPUT DATA'!C56 -> Direktur

Sheet Kuitansi
C11: KUITANSI PEMBAYARAN
H13: Tahun Anggaran | J13: : | K13: ='In Data'!C49 -> 2026
H14: Nomor | J14: : | K14: ='In Data'!C11 -> 050102/CV.AFWAN/02/2026
H15: Sumber Dana | J15: : | K15: ='In Data'!C50 -> BOSP
B17: Sudah diterima dari | D17: : | E17: ='In Data'!C18 -> SMA NEGERI 1 PAGELARAN
B18: Jumlah uang | D18: : | E18: ='In Data'!C41 -> 15000000
B19: Terbilang | D19: : | E19: ='In Data'!C42 -> #NAME? | F19: 0 | G19: 0 | H19: 0 | I19: 0 | J19: 0 | K19: 0
B20: Untuk Pembayaran | D20: : | E20: ='In Data'!C38 -> Belanja Alat Tulis Kantor
J22: ="Cianjur, "&'In Data'!E11&"" -> Cianjur, 05 Februari 2026
C23: Diserahkan Oleh, | J23: Diterima Oleh,
C24: Kepala Sekolah | J24: ='In Data'!C68 -> CV. AFWAN
C33: ='In Data'!C26 -> Fitri Yurnita, S.Pd | J33: ='In Data'!C54 -> Mega Afriyanti, S.Pd
C34: ="NIP. "&'In Data'!C27&"" -> NIP. 198008142009032002 | J34: ='[2]INPUT DATA'!C56 -> Direktur
C37: Barang/Pekerjaan tersebut telah diterima/diselesaikan dengan lengkap dan baik
C38: Pemeriksa Barang
C47: ='In Data'!C32 -> Hamdani
C48: ="NIP. "&'In Data'!C33&"" -> NIP. -

Sheet Cover
C17: ='In Data'!C15 -> PEMERINTAH DAERAH PROVINSI JAWA BARAT
C19: ='In Data'!C18 -> SMA NEGERI 1 PAGELARAN
C21: ='In Data'!C21 -> Jalan Raya Pagelaran Kp. Cibeureum Desa Sindangkerta Rt. 06/Rw. 07 Pagelaran – Cianjur 43266
C26: KUITANSI :
C27: ='In Data'!C11 -> 050102/CV.AFWAN/02/2026
C28: ="Tangga "&'In Data'!E11&"" -> Tangga 05 Februari 2026
C36: TENTANG :
C37: PAKET PEKERJAAN
C38: ='In Data'!C38 -> Belanja Alat Tulis Kantor
C39: ="DILINGKUNGAN "&'In Data'!C18&"" -> DILINGKUNGAN SMA NEGERI 1 PAGELARAN
C46: HARGA | D46: : | E46: ='In Data'!C43 -> Rp. 15.000.000
C47: TERBILANG | D47: : | E47: ='In Data'!C44 -> #NAME?
C48: REKANAN PELAKSANA | D48: : | E48: ='In Data'!C68 -> CV. AFWAN
C49: ALAMAT | D49: : | E49: ='In Data'!C69 -> Kp. Cangklek No. 61 RT.004 / RW.001 Sukamanah, Cugenang, Cianjur Jawa barat
C52: CIANJUR
C53: ="TAHUN ANGGARAN "&'In Data'!C49&" " -> TAHUN ANGGARAN 2026

Sheet Identitas Penyedia
B2: IDENTITAS PENYEDIA
B4: Saya yang bertanda tangan di bawah ini:
B5: Nama | F5: : | G5: ='In Data'!C54 -> Mega Afriyanti, S.Pd
B6: No. Identitas | F6: : | G6: ='In Data'!C55 -> 3203114504870009
B7: Jabatan | F7: : | G7: ='In Data'!C58 -> Direktur
B8: Bertindak untuk dan atas nama | F8: : | G8: ='In Data'!C68 -> CV. AFWAN
B9: Alamat | F9: : | G9: ='In Data'!C69 -> Kp. Cangklek No. 61 RT.004 / RW.001 Sukamanah, Cugenang, Cianjur Jawa barat
B10: Telepon/Fax | F10: : | G10: ='In Data'!C60 -> 085691768167
B11: Email | F11: : | G11: ='In Data'!C71 -> cv.afwan@gmail.com
B13: Menyatakan dengan sesungguhnya bahwa:
B14: 1. | C14: ="Saya secara hukum bertindak untuk dan atas nama "&" berdasarkan Akte Pendirian Nomor "&" dengan Notaris "&" tanggal "&"" -> Saya secara hukum bertindak untuk dan atas nama berdasarkan Akte Pendirian Nomor dengan Notaris tanggal
B15: 2. | C15: Saya bukan sebagai pegawai Pegawai Negeri Sipil, Anggota TNI/POLRI, Pegawai BUMN;
B16: 3. | C16: Saya tidak sedang menjalani sanksi pidana;
B17: 4. | C17: Saya tidak sedang dan tidak akan terlibat pertentangan kepentingan dengan para pihak yang terkait, langsung maupun tidak langsung dalam proses pengadaan ini;
B18: 5. | C18: Badan usaha yang saya wakili tidak masuk dalam Daftar Hitam, tidak dalam pengawasan pengadilan, tidak pailit atau kegiatan usahanya tidak sedang dihentikan;
B19: 6. | C19: Salah satu dan/atau semua pengurus badan usaha yang saya wakili tidak masuk dalam Daftar Hitam;
B20: 7. | C20: Data-data badan usaha yang saya wakili adalah sebagai berikut:
B22: A. | C22: Data Administrasi
C23: 1. | D23: Nama Badan Usaha | J23: : | K23: ='In Data'!C68 -> CV. AFWAN
C25: 2. | D25: Status | J25: : | K25: √ | L25: PUSAT | N25: CABANG
C27: 3. | D27: Alamat Kantor Pusat | J27: : | K27: ='In Data'!C69 -> Kp. Cangklek No. 61 RT.004 / RW.001 Sukamanah, Cugenang, Cianjur Jawa barat
D28: No. Telepon | J28: : | K28: ='In Data'!C60 -> 085691768167
D29: No. Fax | J29: : | K29: __________
D30: E-Mail | J30: : | K30: ='In Data'!C71 -> cv.afwan@gmail.com
C31: 4. | D31: Alamat Kantor Cabang | J31: : | K31: __________
D32: No. Telepon | J32: : | K32: __________
D33: No. Fax | J33: : | K33: __________
D34: E-Mail | J34: : | K34: __________
B36: B. | C36: Landasan Hukum Pendirian Perusahaan
C37: 1. | D37: Akta Pendirian Perusahaan/Anggaran Dasar Koperasi
D38: a. | E38: Nomor | J38: : | K38: ='In Data'!C75 -> -
D39: b. | E39: Tanggal | J39: : | K39: ='In Data'!C76 -> -
D40: c. | E40: Nama Notaris | J40: : | K40: ='In Data'!C77 -> -
D41: d. | E41: Nomor Pengesahan Kementerian Hukum dan HAM. (untuk yang berbentuk PT)
C42: 2. | D42: Perubahan Terakhir Akta Pendirian Perusahaan /Anggaran Dasar Koperasi
D43: a. | E43: Nomor | J43: : | K43: ='In Data'!C75 -> -
D44: b. | E44: Tanggal | J44: : | K44: ='In Data'!C76 -> -
D45: c. | E45: Nama Notaris | J45: : | K45: ='In Data'!C77 -> -
B47: C. | C47: Pengurus Badan Usaha
C48: No. | D48: Nama | H48: No. Identitas | K48: Jabatan dalam Badan Usaha
...
